Workbook

Sheet Pivot Table
A2: Row Labels | B2: Count of 100% Attendance [Aundh] | C2: Count of 100% Attendance [Kondhwa] | D2: Count of 100% Attendance [Sinhgad Road]
A3: Aarav Patil | B3: 1 | C3: 1 | D3: 1
A4: Meera Kumar | B4: 1 | C4: 1 | D4: 1
A5: daksh sharma | B5: 1 | C5: 1 | D5: 1
A6: Atharva Deshmukh | B6: 1 | C6: 1 | D6: 1
A7: Ira Kumar | B7: 1 | C7: 1 | D7: 1
A8: prem patil | B8: 1 | C8: 1 | D8: 1
A9: aryan patil | B9: 1 | C9: 1 | D9: 1
A10: Gandhar Kulkarni | B10: 1 | C10: 1 | D10: 1
A11: Ayaan Joshi | B11: 1 | C11: 1 | D11: 1
A12: Vedant Jadhav | B12: 1 | C12: 1 | D12: 1
A13: Hrishikesh Gokhale | B13: 1 | C13: 1 | D13: 1
A14: Siya Kumar | B14: 1 | C14: 1 | D14: 1
A15: Grand Total | B15: 4 | C15: 4 | D15: 4

Sheet Combined attendance
A1: Aundh Attendance | D1: Kondhwa Attendance | G1: Sinhgad Road Attendance
A2: Student Name [Aundh] | B2: Attendance [Aundh] | C2: 100% Attendance [Aundh] | D2: Student Name [Kondhwa] | E2: Attendance [Kondhwa] | F2: 100% Attendance [Kondhwa] | G2: Student Name [Sinhgad_Road] | H2: Attendance [Sinhgad_Road] | I2: 100% Attendance [Sinhgad Road]
A3: Aarav Patil | B3: {=VLOOKUP(A3:A51,Aundh!B:AM,39,0)} -> #REF! | C3: {=_xlfn._xlws.FILTER(A3:A50, B3:B50=100, "No students with 100% attendance")} -> #REF! | D3: aarav sharma | E3: {=VLOOKUP(D3:D51,Kondhwa!B:AM,39,0)} -> #REF! | F3: {=_xlfn._xlws.FILTER(D3:D50, E3:E50=100, "No students with 100% attendance")} -> #REF! | G3: daksh sharma | H3: {=VLOOKUP(G3:G51,Sinhgad_Road!B:AM,39,0)} -> #REF! | I3: {=_xlfn._xlws.FILTER(G3:G50, H3:H50=100, "No students with 100% attendance")} -> #REF!
A4: Atharva Deshmukh | B4: #REF! | D4: Aditya Kadam | E4: #REF! | G4: prem patil | H4: #REF!
A5: aryan patil | B5: #REF! | D5: Aniket Jadhav | E5: #REF! | G5: Ayaan Joshi | H5: #REF!
A6: Kabir Desai | B6: #REF! | D6: Meera Kumar | E6: #REF! | G6: ram sharma | H6: #REF!
A7: Vivaan Kulkarni | B7: #REF! | D7: Ira Kumar | E7: #REF! | G7: Anaya Joshi | H7: #REF!
A8: Reyansh Sharma | B8: #REF! | D8: Atharva Gaikwad | E8: #REF! | G8: ayra sharma | H8: #REF!
A9: Siddharth Joshi | B9: #REF! | D9: Chinmay Deo | E9: #REF! | G9: Kabir Desai | H9: #REF!
A10: Anay Shinde | B10: #REF! | D10: Aarav Patil | E10: #REF! | G10: Anaya Desai | H10: #REF!
A11: Ishaan Chavan | B11: #REF! | D11: Ira Patil | E11: #REF! | G11: Meera Patil | H11: #REF!
A12: Ira Joshi | B12: #REF! | D12: Reyansh Joshi | E12: #REF! | G12: pratik kumar | H12: #REF!
A13: Omkar Bhosale | B13: #REF! | D13: Digvijay Mohite | E13: #REF! | G13: Aarav Desai | H13: #REF!
A14: Rudra Gaikwad | B14: #REF! | D14: Durvesh Raut | E14: #REF! | G14: pratik more | H14: #REF!
A15: Vedant Jadhav | B15: #REF! | D15: Ayaan Joshi | E15: #REF! | G15: shubham pawar | H15: #REF!
... A51: Anaya Desai | B51: #REF! | D51: Siya Joshi | E51: #REF! | G51: Vivaan Joshi | H51: #REF!

Sheet Aundh
A1: Student ID | B1: Student Name | C1: Date of Birth | D1: Gender | E1: Parent Contact Number | F1: Student Email | G1: Address | H1: School/College Name | I1: Previous Academic Performance (%) | J1: Emergency Contact | K1: Course | L1: Course Duration (Months) | M1: Batch | N1: Batch Start Date | O1: Batch End Date | P1: Classroom/Room No. | Q1: Mode | R1: Session Days | S1: Subject | T1: Teacher | U1: Enrollment Date | V1: Registration Date | W1: Total Course Fees | X1: Amount Paid | Y1: Pending Amount | Z1: Discount Given | AA1: Installment Plan | AB1: Next Payment Due Date | AC1: Payment Status | AD1: Payment Method | AE1: Number of Tests Taken | AF1: Average Test Score | AG1: Top Test Score | AH1: Progress Comments | AI1: Homework Completion Rate (%) | AJ1: Total Classes Conducted | AK1: Classes Attended | AL1: Leave Notes/Remarks | AM1: Attendance (%) | AN1: Attendance Alerts Sent | AO1: Parent Feedback | AP1: Student Feedback | AQ1: Last Feedback Date | AR1: Follow-up Date | AS1: WhatsApp Opt-in | AT1: Lead Source | AU1: Counselor/Admission Handled By | AV1: Dropout Status | AW1: Reason for Leaving
A2: AU-007 | B2: Aarav Patil | C2: 2006-05-20 | D2: Female | E2: 9827095765 | F2: ira.sharma7@gmail.com | G2: 318, Aundh Pune | H2: City International School | I2: 82 | J2: 9953297386 | K2: Foundation 8-10 | L2: 6 | M2: Evening | N2: 2024-01-28 | O2: 2024-07-26 | P2: R-111 | Q2: Offline | R2: Tue-Thu-Sat | S2: Maths | T2: Preeti Desai | U2: 2024-05-20 | V2: 2024-05-15 | W2: 43018 | X2: 39256 | Y2: 3762 | Z2: 4189 | AA2: No | AB2: =RANDBETWEEN(DATE(2025,7,1),DATE(2025,12,31)) -> 46020 | AC2: Partial | AD2: UPI | AE2: 5 | AF2: 41 | AG2: 77 | AH2: Average | AI2: 81 | AJ2: 24 | AK2: 24 | AL2: Family function | AM2: 100 | AN2: Yes | AO2: 3 | AP2: 5 | AQ2: 2024-07-11 | AR2: 2024-08-09 | AS2: No | AT2: Facebook Ad | AU2: Nidhi Shah | AV2: Left | AW2: Switched institute
A3: AU-048 | B3: Atharva Deshmukh | C3: 2006-07-29 | D3: Female | E3: 9895313505 | F3: aarav.kumar48@gmail.com | G3: 937, Aundh Pune | H3: Modern College | I3: 87 | J3: 9912189875 | K3: Foundation 8-10 | L3: 3 | M3: Afternoon | N3: 2024-01-15 | O3: 2024-04-14 | P3: R-118 | Q3: Offline | R3: Mon-Wed-Fri | S3: Physics | T3: Ravi Kumar | U3: 2024-04-01 | V3: 2024-03-25 | W3: 20086 | X3: 19800 | Y3: 286 | Z3: 1952 | AA3: No | AB3: =RANDBETWEEN(DATE(2025,7,1),DATE(2025,12,31)) -> 45917 | AC3: Partial | AD3: Bank Transfer | AE3: 9 | AF3: 67 | AG3: 86 | AH3: Good | AI3: 67 | AJ3: 22 | AK3: 22 | AM3: 100 | AN3: No | AO3: 5 | AP3: 4 | AQ3: 2024-04-23 | AR3: 2024-05-06 | AS3: No | AT3: Instagram Ad | AU3: Amit Deshmukh | AV3: Left | AW3: Too far
A4: AU-015 | B4: aryan patil | C4: 2006-07-12 | D4: Female | E4: 9827032133 | F4: aarav.patil15@gmail.com | G4: 694, Aundh Pune | H4: Vidyanchal School | I4: 79 | J4: 9919617248 | K4: NEET | L4: 6 | M4: Morning | N4: 2024-01-23 | O4: 2024-07-21 | P4: R-107 | Q4: Hybrid | R4: Mon-Wed-Fri | S4: Chemistry | T4: Sneha Patil | U4: 2024-02-08 | V4: 2024-02-06 | W4: 33714 | X4: 33476 | Y4: 238 | Z4: 1249 | AA4: Yes | AB4: =RANDBETWEEN(DATE(2025,7,1),DATE(2025,12,31)) -> 45999 | AC4: Partial | AD4: Bank Transfer | AE4: 8 | AF4: 66 | AG4: 79 | AH4: Needs Improvement | AI4: 85 | AJ4: 51 | AK4: 50 | AM4: 100 | AN4: No | AO4: 2 | AP4: 5 | AQ4: 2024-03-01 | AR4: 2024-03-14 | AS4: No | AT4: Website | AU4: Amit Deshmukh | AV4: Left | AW4: Switched institute
A5: AU-044 | B5: Kabir Desai | C5: 2005-09-24 | D5: Male | E5: 9861278670 | F5: kabir.desai44@gmail.com | G5: 169, Aundh Pune | H5: D.A.V. Public School | I5: 70 | J5: 9926091051 | K5: MHT-CET | L5: 6 | M5: Morning | N5: 2024-02-11 | O5: 2024-08-09 | P5: R-120 | Q5: Hybrid | R5: Tue-Thu-Sat | S5: Chemistry | T5: Anil Sharma | U5: 2024-04-12 | V5: 2024-04-09 | W5: 26521 | X5: 25742 | Y5: 779 | Z5: 1089 | AA5: No | AB5: =RANDBETWEEN(DATE(2025,7,1),DATE(2025,12,31)) -> 45923 | AC5: Partial | AD5: UPI | AE5: 7 | AF5: 79 | AG5: 79 | AH5: Good | AI5: 78 | AJ5: 36 | AK5: 35 | AM5: 97 | AN5: Yes | AO5: 5 | AP5: 1 | AQ5: 2024-05-08 | AR5: 2024-05-31 | AS5: Yes | AT5: Instagram Ad | AU5: Amit Deshmukh | AV5: Left | AW5: Lost interest
A6: AU-017 | B6: Vivaan Kulkarni | C6: 2005-06-15 | D6: Female | E6: 9810220839 | F6: anaya.joshi17@gmail.com | G6: 751, Aundh Pune | H6: City School | I6: 75 | J6: 9963948363 | K6: NEET | L6: 12 | M6: Morning | N6: 2024-01-20 | O6: 2025-01-14 | P6: R-104 | Q6: Offline | R6: Tue-Thu-Sat | S6: Physics | T6: Anil Sharma | U6: 2024-02-24 | V6: 2024-02-24 | W6: 41229 | X6: 40571 | Y6: 658 | Z6: 4623 | AA6: Yes | AB6: =RANDBETWEEN(DATE(2025,7,1),DATE(2025,12,31)) -> 45864 | AC6: Partial | AD6: Bank Transfer | AE6: 6 | AF6: 41 | AG6: 93 | AH6: Needs Improvement | AI6: 85 | AJ6: 33 | AK6: 32 | AM6: 96 | AN6: Yes | AO6: 1 | AP6: 1 | AQ6: 2024-03-26 | AR6: 2024-04-21 | AS6: Yes | AT6: Instagram Ad | AU6: Rahul Mehta | AV6: Left | AW6: Switched institute
A7: AU-001 | B7: Reyansh Sharma | C7: 2005-01-18 | D7: Female | E7: 9855426302 | F7: reyansh.sharma1@gmail.com | G7: 463, Aundh Pune | H7: Vidyanchal School | I7: 77 | J7: 9926479089 | K7: Foundation 8-10 | L7: 12 | M7: Evening | N7: 2024-01-02 | O7: 2024-12-27 | P7: R-113 | Q7: Hybrid | R7: Tue-Thu-Sat | S7: Maths | T7: Preeti Desai | U7: 2024-04-20 | V7: 2024-04-14 | W7: 42851 | X7: 40171 | Y7: 2680 | Z7: 4474 | AA7: No | AB7: =RANDBETWEEN(DATE(2025,7,1),DATE(2025,12,31)) -> 45892 | AC7: Partial | AD7: Card | AE7: 1 | AF7: 46 | AG7: 96 | AH7: Average | AI7: 71 | AJ7: 45 | AK7: 43 | AM7: 95 | AN7: No | AO7: 2 | AP7: 4 | AQ7: 2024-05-14 | AR7: 2024-06-08 | AS7: No | AT7: Referral | AU7: Amit Deshmukh | AV7: Left | AW7: Lost interest
A8: AU-030 | B8: Siddharth Joshi | C8: 2005-04-23 | D8: Male | E8: 9895766321 | F8: aarav.desai30@gmail.com | G8: 870, Aundh Pune | H8: D.A.V. Public School | I8: 94 | J8: 9975991785 | K8: NEET | L8: 3 | M8: Afternoon | N8: 2024-01-06 | O8: 2024-04-05 | P8: R-120 | Q8: Online | R8: Mon-Wed-Fri | S8: Maths | T8: Vikram Joshi | U8: 2024-02-24 | V8: 2024-02-15 | W8: 21243 | X8: 20076 | Y8: 1167 | Z8: 3153 | AA8: Yes | AB8: =RANDBETWEEN(DATE(2025,7,1),DATE(2025,12,31)) -> 45982 | AC8: Partial | AD8: Cash | AE8: 2 | AF8: 67 | AG8: 70 | AH8: Needs Improvement | AI8: 82 | AJ8: 60 | AK8: 57 | AL8: Family function | AM8: 95 | AN8: Yes | AO8: 5 | AP8: 4 | AQ8: 2024-04-03 | AR8: 2024-04-21 | AS8: Yes | AT8: Walk-in | AU8: Rahul Mehta | AV8: Active
A9: AU-014 | B9: Anay Shinde | C9: 2006-06-06 | D9: Male | E9: 9822011112 | F9: vivaan.joshi14@gmail.com | G9: 738, Aundh Pune | H9: Modern College | I9: 62 | J9: 9953143872 | K9: JEE | L9: 12 | M9: Morning | N9: 2024-03-22 | O9: 2025-03-17 | P9: R-114 | Q9: Online | R9: Tue-Thu-Sat | S9: Biology | T9: Anil Sharma | U9: 2024-02-25 | V9: 2024-02-25 | W9: 24474 | X9: 20873 | Y9: 3601 | Z9: 4292 | AA9: No | AB9: =RANDBETWEEN(DATE(2025,7,1),DATE(2025,12,31)) -> 45930 | AC9: Partial | AD9: Card | AE9: 6 | AF9: 44 | AG9: 50 | AH9: Needs Improvement | AI9: 91 | AJ9: 34 | AK9: 32 | AM9: 94 | AN9: No | AO9: 2 | AP9: 1 | AQ9: 2024-03-16 | AR9: 2024-04-06 | AS9: No | AT9: Walk-in | AU9: Nidhi Shah | AV9: Active
A10: AU-018 | B10: Ishaan Chavan | C10: 2005-05-10 | D10: Male | E10: 9864434821 | F10: anaya.kumar18@gmail.com | G10: 551, Aundh Pune | H10: Modern College | I10: 71 | J10: 9951130048 | K10: NEET | L10: 12 | M10: Morning | N10: 2024-01-05 | O10: 2024-12-30 | P10: R-101 | Q10: Hybrid | R10: Tue-Thu-Sat | S10: Biology | T10: Anil Sharma | U10: 2024-03-06 | V10: 2024-03-05 | W10: 29689 | X10: 28607 | Y10: 1082 | Z10: 1301 | AA10: Yes | AB10: =RANDBETWEEN(DATE(2025,7,1),DATE(2025,12,31)) -> 45897 | AC10: Partial | AD10: Card | AE10: 4 | AF10: 54 | AG10: 74 | AH10: Needs Improvement | AI10: 90 | AJ10: 56 | AK10: 53 | AL10: Family function | AM10: 94 | AN10: Yes | AO10: 2 | AP10: 5 | AQ10: 2024-04-17 | AR10: 2024-05-15 | AS10: No | AT10: Instagram Ad | AU10: Amit Deshmukh | AV10: Left | AW10: Too far
A11: AU-020 | B11: Ira Joshi | C11: 2006-01-28 | D11: Male | E11: 9898616022 | F11: ira.joshi20@gmail.com | G11: 236, Aundh Pune | H11: Modern College | I11: 67 | J11: 9921755464 | K11: JEE | L11: 3 | M11: Morning | N11: 2024-03-03 | O11: 2024-06-01 | P11: R-109 | Q11: Online | R11: Tue-Thu-Sat | S11: Chemistry | T11: Anil Sharma | U11: 2024-03-12 | V11: 2024-03-10 | W11: 15521 | X11: 15338 | Y11: 183 | Z11: 1968 | AA11: No | AB11: =RANDBETWEEN(DATE(2025,7,1),DATE(2025,12,31)) -> 45994 | AC11: Partial | AD11: Bank Transfer | AE11: 5 | AF11: 81 | AG11: 87 | AH11: Average | AI11: 77 | AJ11: 56 | AK11: 53 | AL11: Sick leave | AM11: 94 | AN11: Yes | AO11: 2 | AP11: 4 | AQ11: 2024-04-25 | AR11: 2024-05-05 | AS11: No | AT11: Website | AU11: Amit Deshmukh | AV11: Left | AW11: Switched institute
A12: AU-047 | B12: Omkar Bhosale | C12: 2005-11-14 | D12: Male | E12: 9886591060 | F12: riya.patil47@gmail.com | G12: 113, Aundh Pune | H12: Vidyanchal School | I12: 76 | J12: 9978630854 | K12: JEE | L12: 6 | M12: Morning | N12: 2024-04-04 | O12: 2024-10-01 | P12: R-111 | Q12: Hybrid | R12: Mon-Wed-Fri | S12: Physics | T12: Vikram Joshi | U12: 2024-02-12 | V12: 2024-02-02 | W12: 47666 | X12: 47504 | Y12: 162 | Z12: 365 | AA12: Yes | AB12: =RANDBETWEEN(DATE(2025,7,1),DATE(2025,12,31)) -> 45953 | AC12: Partial | AD12: Bank Transfer | AE12: 6 | AF12: 73 | AG12: 82 | AH12: Good | AI12: 75 | AJ12: 25 | AK12: 23 | AL12: Family function | AM12: 92 | AN12: Yes | AO12: 4 | AP12: 3 | AQ12: 2024-03-15 | AR12: 2024-04-01 | AS12: No | AT12: Walk-in | AU12: Amit Deshmukh | AV12: Left | AW12: Too far
A13: AU-028 | B13: Rudra Gaikwad | C13: 2006-06-28 | D13: Female | E13: 9814694076 | F13: meera.joshi28@gmail.com | G13: 113, Aundh Pune | H13: Modern College | I13: 84 | J13: 9969698577 | K13: JEE | L13: 12 | M13: Morning | N13: 2024-01-11 | O13: 2025-01-05 | P13: R-102 | Q13: Hybrid | R13: Mon-Wed-Fri | S13: Physics | T13: Vikram Joshi | U13: 2024-02-11 | V13: 2024-02-04 | W13: 31688 | X13: 31188 | Y13: 500 | Z13: 1442 | AA13: No | AB13: =RANDBETWEEN(DATE(2025,7,1),DATE(2025,12,31)) -> 45859 | AC13: Partial | AD13: Cash | AE13: 10 | AF13: 71 | AG13: 91 | AH13: Good | AI13: 80 | AJ13: 24 | AK13: 22 | AM13: 91 | AN13: No | AO13: 3 | AP13: 3 | AQ13: 2024-04-05 | AR13: 2024-05-01 | AS13: Yes | AT13: Instagram Ad | AU13: Amit Deshmukh | AV13: Left | AW13: Too far
A14: AU-043 | B14: Vedant Jadhav | C14: 2005-05-30 | D14: Male | E14: 9827525677 | F14: ayaan.joshi43@gmail.com | G14: 318, Aundh Pune | H14: Spicer Higher Secondary School | I14: 93 | J14: 9973127650 | K14: Foundation 8-10 | L14: 3 | M14: Morning | N14: 2024-03-23 | O14: 2024-06-21 | P14: R-116 | Q14: Hybrid | R14: Mon-Wed-Fri | S14: Physics | T14: Sneha Patil | U14: 2024-03-18 | V14: 2024-03-18 | W14: 33476 | X14: 32565 | Y14: 911 | Z14: 922 | AA14: Yes | AB14: =RANDBETWEEN(DATE(2025,7,1),DATE(2025,12,31)) -> 45883 | AC14: Partial | AD14: Bank Transfer | AE14: 8 | AF14: 50 | AG14: 75 | AH14: Good | AI14: 94 | AJ14: 37 | AK14: 34 | AL14: Sick leave | AM14: 100 | AN14: Yes | AO14: 1 | AP14: 4 | AQ14: 2024-04-19 | AR14: 2024-04-29 | AS14: Yes | AT14: Website | AU14: Rahul Mehta | AV14: Left | AW14: Lost interest
A15: AU-031 | B15: Vivaan Joshi | C15: 2005-04-09 | D15: Male | E15: 9885303785 | F15: vivaan.joshi31@gmail.com | G15: 460, Aundh Pune | H15: City International School | I15: 75 | J15: 9990322781 | K15: Foundation 8-10 | L15: 12 | M15: Evening | N15: 2024-02-15 | O15: 2025-02-09 | P15: R-103 | Q15: Hybrid | R15: Tue-Thu-Sat | S15: Chemistry | T15: Preeti Desai | U15: 2024-02-17 | V15: 2024-02-14 | W15: 42334 | X15: 40547 | Y15: 1787 | Z15: 4132 | AA15: Yes | AB15: =RANDBETWEEN(DATE(2025,7,1),DATE(2025,12,31)) -> 45917 | AC15: Partial | AD15: Bank Transfer | AE15: 7 | AF15: 53 | AG15: 85 | AH15: Average | AI15: 98 | AJ15: 20 | AK15: 18 | AM15: 90 | AN15: No | AO15: 3 | AP15: 5 | AQ15: 2024-03-30 | AR15: 2024-04-26 | AS15: Yes | AT15: Walk-in | AU15: Nidhi Shah | AV15: Left | AW15: Lost interest
A16: AU-006 | B16: Meera Desai | C16: 2006-05-16 | D16: Male | E16: 9820367740 | F16: meera.desai6@gmail.com | G16: 368, Aundh Pune | H16: Spicer Higher Secondary School | I16: 89 | J16: 9952336944 | K16: MHT-CET | L16: 3 | M16: Morning | N16: 2024-03-12 | O16: 2024-06-10 | P16: R-120 | Q16: Offline | R16: Mon-Wed-Fri | S16: Biology | T16: Preeti Desai | U16: 2024-03-06 | V16: 2024-02-28 | W16: 40557 | X16: 40142 | Y16: 415 | Z16: 1522 | AA16: Yes | AB16: =RANDBETWEEN(DATE(2025,7,1),DATE(2025,12,31)) -> 46009 | AC16: Partial | AD16: Cash | AE16: 4 | AF16: 69 | AG16: 93 | AH16: Good | AI16: 61 | AJ16: 52 | AK16: 46 | AL16: Family function | AM16: 88 | AN16: No | AO16: 2 | AP16: 2 | AQ16: 2024-03-27 | AR16: 2024-04-22 | AS16: Yes | AT16: Facebook Ad | AU16: Rahul Mehta | AV16: Active
A17: AU-033 | B17: Kabir Patil | C17: 2005-06-09 | D17: Male | E17: 9845974289 | F17: kabir.patil33@gmail.com | G17: 395, Aundh Pune | H17: Modern College | I17: 93 | J17: 9934055823 | K17: MHT-CET | L17: 3 | M17: Morning | N17: 2024-02-01 | O17: 2024-05-01 | P17: R-112 | Q17: Online | R17: Mon-Wed-Fri | S17: Biology | T17: Vikram Joshi | U17: 2024-02-21 | V17: 2024-02-11 | W17: 21123 | X17: 20086 | Y17: 1037 | Z17: 2663 | AA17: No | AB17: =RANDBETWEEN(DATE(2025,7,1),DATE(2025,12,31)) -> 45952 | AC17: Partial | AD17: UPI | AE17: 2 | AF17: 40 | AG17: 68 | AH17: Good | AI17: 97 | AJ17: 48 | AK17: 42 | AL17: Sick leave | AM17: 87 | AN17: No | AO17: 5 | AP17: 1 | AQ17: 2024-04-05 | AR17: 2024-04-27 | AS17: No | AT17: Instagram Ad | AU17: Nidhi Shah | AV17: Left | AW17: Switched institute
A18: AU-024 | B18: Meera Sharma | C18: 2006-02-20 | D18: Male | E18: 9871747241 | F18: meera.sharma24@gmail.com | G18: 209, Aundh Pune | H18: Modern College | I18: 67 | J18: 9937156335 | K18: MHT-CET | L18: 3 | M18: Morning | N18: 2024-02-19 | O18: 2024-05-19 | P18: R-103 | Q18: Hybrid | R18: Tue-Thu-Sat | S18: Maths | T18: Preeti Desai | U18: 2024-05-10 | V18: 2024-05-09 | W18: 36359 | X18: 34507 | Y18: 1852 | Z18: 2266 | AA18: Yes | AB18: =RANDBETWEEN(DATE(2025,7,1),DATE(2025,12,31)) -> 45892 | AC18: Partial | AD18: Bank Transfer | AE18: 4 | AF18: 48 | AG18: 54 | AH18: Average | AI18: 72 | AJ18: 23 | AK18: 20 | AL18: Sick leave | AM18: 86 | AN18: No | AO18: 1 | AP18: 4 | AQ18: 2024-07-09 | AR18: 2024-08-03 | AS18: Yes | AT18: Instagram Ad | AU18: Nidhi Shah | AV18: Left | AW18: Lost interest
A19: AU-019 | B19: Aarav Desai | C19: 2006-02-07 | D19: Male | E19: 9888818798 | F19: aarav.desai19@gmail.com | G19: 894, Aundh Pune | H19: City International School | I19: 70 | J19: 9941695896 | K19: MHT-CET | L19: 12 | M19: Evening | N19: 2024-03-25 | O19: 2025-03-20 | P19: R-107 | Q19: Offline | R19: Mon-Wed-Fri | S19: Maths | T19: Sneha Patil | U19: 2024-04-27 | V19: 2024-04-26 | W19: 17919 | X19: 17530 | Y19: 389 | Z19: 511 | AA19: Yes | AB19: =RANDBETWEEN(DATE(2025,7,1),DATE(2025,12,31)) -> 45981 | AC19: Partial | AD19: Bank Transfer | AE19: 8 | AF19: 53 | AG19: 86 | AH19: Good | AI19: 82 | AJ19: 28 | AK19: 24 | AL19: Sick leave | AM19: 85 | AN19: Yes | AO19: 2 | AP19: 3 | AQ19: 2024-06-10 | AR19: 2024-07-03 | AS19: No | AT19: Instagram Ad | AU19: Nidhi Shah | AV19: Active
A20: AU-010 | B20: Vivaan Patil | C20: 2006-04-24 | D20: Male | E20: 9852635954 | F20: vivaan.patil10@gmail.com | G20: 189, Aundh Pune | H20: Vidyanchal School | I20: 64 | J20: 9951085984 | K20: Foundation 8-10 | L20: 3 | M20: Evening | N20: 2024-03-16 | O20: 2024-06-14 | P20: R-108 | Q20: Online | R20: Mon-Wed-Fri | S20: English | T20: Vikram Joshi | U20: 2024-05-08 | V20: 2024-05-08 | W20: 43563 | X20: 43281 | Y20: 282 | Z20: 3482 | AA20: Yes | AB20: =RANDBETWEEN(DATE(2025,7,1),DATE(2025,12,31)) -> 45989 | AC20: Partial | AD20: Bank Transfer | AE20: 9 | AF20: 81 | AG20: 91 | AH20: Needs Improvement | AI20: 97 | AJ20: 28 | AK20: 23 | AL20: Family function | AM20: 82 | AN20: No | AO20: 4 | AP20: 4 | AQ20: 2024-06-03 | AR20: 2024-06-14 | AS20: No | AT20: Website | AU20: Nidhi Shah | AV20: Active
A21: AU-002 | B21: manish sisodia | C21: 2005-09-11 | D21: Female | E21: 9856784978 | F21: aarav.kumar2@gmail.com | G21: 445, Aundh Pune | H21: City School | I21: 73 | J21: 9982991179 | K21: Foundation 8-10 | L21: 6 | M21: Morning | N21: 2024-01-15 | O21: 2024-07-13 | P21: R-102 | Q21: Hybrid | R21: Tue-Thu-Sat | S21: Maths | T21: Preeti Desai | U21: 2024-04-18 | V21: 2024-04-12 | W21: 27267 | X21: 25250 | Y21: 2017 | Z21: 3626 | AA21: No | AB21: =RANDBETWEEN(DATE(2025,7,1),DATE(2025,12,31)) -> 45871 | AC21: Partial | AD21: Bank Transfer | AE21: 6 | AF21: 75 | AG21: 77 | AH21: Good | AI21: 94 | AJ21: 21 | AK21: 17 | AL21: Family function | AM21: 80 | AN21: Yes | AO21: 3 | AP21: 4 | AQ21: 2024-05-08 | AR21: 2024-05-27 | AS21: No | AT21: Instagram Ad | AU21: Amit Deshmukh | AV21: Left | AW21: Switched institute
A22: AU-026 | B22: Kabir Joshi | C22: 2005-10-12 | D22: Male | E22: 9839141596 | F22: kabir.joshi26@gmail.com | G22: 681, Aundh Pune | H22: Modern College | I22: 92 | J22: 9967762687 | K22: JEE | L22: 3 | M22: Evening | N22: 2024-02-24 | O22: 2024-05-24 | P22: R-110 | Q22: Online | R22: Tue-Thu-Sat | S22: Chemistry | T22: Preeti Desai | U22: 2024-05-26 | V22: 2024-05-18 | W22: 38039 | X22: 34261 | Y22: 3778 | Z22: 4859 | AA22: No | AB22: =RANDBETWEEN(DATE(2025,7,1),DATE(2025,12,31)) -> 45897 | AC22: Partial | AD22: Cash | AE22: 8 | AF22: 49 | AG22: 68 | AH22: Needs Improvement | AI22: 84 | AJ22: 51 | AK22: 41 | AM22: 80 | AN22: No | AO22: 3 | AP22: 5 | AQ22: 2024-07-21 | AR22: 2024-08-15 | AS22: Yes | AT22: Walk-in | AU22: Rahul Mehta | AV22: Active
A23: AU-003 | B23: Tejas Pawar | C23: 2006-06-27 | D23: Male | E23: 9847094337 | F23: riya.joshi3@gmail.com | G23: 723, Aundh Pune | H23: City School | I23: 61 | J23: 9967496922 | K23: Crash Course | L23: 6 | M23: Afternoon | N23: 2024-01-22 | O23: 2024-07-20 | P23: R-119 | Q23: Offline | R23: Tue-Thu-Sat | S23: Biology | T23: Vikram Joshi | U23: 2024-05-28 | V23: 2024-05-19 | W23: 29239 | X23: 28279 | Y23: 960 | Z23: 1156 | AA23: No | AB23: =RANDBETWEEN(DATE(2025,7,1),DATE(2025,12,31)) -> 45945 | AC23: Partial | AD23: Cash | AE23: 5 | AF23: 63 | AG23: 64 | AH23: Average | AI23: 68 | AJ23: 54 | AK23: 43 | AL23: Sick leave | AM23: 79 | AN23: Yes | AO23: 1 | AP23: 5 | AQ23: 2024-07-11 | AR23: 2024-07-27 | AS23: Yes | AT23: Website | AU23: Nidhi Shah | AV23: Left | AW23: Switched institute
A24: AU-016 | B24: Anaya Joshi | C24: 2006-08-04 | D24: Male | E24: 9883268727 | F24: anaya.joshi16@gmail.com | G24: 245, Aundh Pune | H24: Modern College | I24: 90 | J24: 9982569341 | K24: Foundation 8-10 | L24: 3 | M24: Afternoon | N24: 2024-01-08 | O24: 2024-04-07 | P24: R-110 | Q24: Hybrid | R24: Tue-Thu-Sat | S24: English | T24: Sneha Patil | U24: 2024-04-13 | V24: 2024-04-11 | W24: 30207 | X24: 28610 | Y24: 1597 | Z24: 1889 | AA24: Yes | AB24: =RANDBETWEEN(DATE(2025,7,1),DATE(2025,12,31)) -> 45864 | AC24: Partial | AD24: Bank Transfer | AE24: 7 | AF24: 52 | AG24: 87 | AH24: Average | AI24: 72 | AJ24: 50 | AK24: 39 | AM24: 78 | AN24: Yes | AO24: 4 | AP24: 3 | AQ24: 2024-05-30 | AR24: 2024-06-25 | AS24: Yes | AT24: Website | AU24: Amit Deshmukh | AV24: Left | AW24: Lost interest
A25: AU-038 | B25: Hriday Limaye | C25: 2006-06-21 | D25: Male | E25: 9822514259 | F25: ayaan.sharma38@gmail.com | G25: 217, Aundh Pune | H25: Modern College | I25: 79 | J25: 9960114318 | K25: NEET | L25: 12 | M25: Evening | N25: 2024-01-22 | O25: 2025-01-16 | P25: R-115 | Q25: Offline | R25: Mon-Wed-Fri | S25: Maths | T25: Vikram Joshi | U25: 2024-05-15 | V25: 2024-05-09 | W25: 45733 | X25: 41468 | Y25: 4265 | Z25: 4465 | AA25: Yes | AB25: =RANDBETWEEN(DATE(2025,7,1),DATE(2025,12,31)) -> 45896 | AC25: Partial | AD25: Bank Transfer | AE25: 5 | AF25: 51 | AG25: 58 | AH25: Average | AI25: 65 | AJ25: 56 | AK25: 44 | AM25: 78 | AN25: No | AO25: 1 | AP25: 3 | AQ25: 2024-07-13 | AR25: 2024-07-25 | AS25: No | AT25: Website | AU25: Nidhi Shah | AV25: Active
A26: AU-008 | B26: Meera Joshi | C26: 2006-06-23 | D26: Female | E26: 9822355416 | F26: meera.joshi8@gmail.com | G26: 589, Aundh Pune | H26: Vidyanchal School | I26: 88 | J26: 9995712675 | K26: Crash Course | L26: 3 | M26: Afternoon | N26: 2024-03-22 | O26: 2024-06-20 | P26: R-105 | Q26: Online | R26: Tue-Thu-Sat | S26: Physics | T26: Sneha Patil | U26: 2024-03-15 | V26: 2024-03-14 | W26: 40970 | X26: 39997 | Y26: 973 | Z26: 2197 | AA26: No | AB26: =RANDBETWEEN(DATE(2025,7,1),DATE(2025,12,31)) -> 45945 | AC26: Partial | AD26: Bank Transfer | AE26: 6 | AF26: 90 | AG26: 99 | AH26: Average | AI26: 72 | AJ26: 33 | AK26: 25 | AL26: Family function | AM26: 75 | AN26: Yes | AO26: 3 | AP26: 5 | AQ26: 2024-04-08 | AR26: 2024-04-21 | AS26: No | AT26: Referral | AU26: Rahul Mehta | AV26: Active
A27: AU-009 | B27: Aryan Apte | C27: 2006-05-21 | D27: Male | E27: 9888752606 | F27: aarav.kumar9@gmail.com | G27: 276, Aundh Pune | H27: City International School | I27: 73 | J27: 9967525295 | K27: Foundation 8-10 | L27: 12 | M27: Afternoon | N27: 2024-03-04 | O27: 2025-02-27 | P27: R-105 | Q27: Online | R27: Mon-Wed-Fri | S27: Chemistry | T27: Vikram Joshi | U27: 2024-03-06 | V27: 2024-03-01 | W27: 21161 | X27: 19825 | Y27: 1336 | Z27: 3988 | AA27: No | AB27: =RANDBETWEEN(DATE(2025,7,1),DATE(2025,12,31)) -> 45993 | AC27: Partial | AD27: UPI | AE27: 8 | AF27: 68 | AG27: 83 | AH27: Good | AI27: 99 | AJ27: 56 | AK27: 41 | AM27: 73 | AN27: No | AO27: 2 | AP27: 5 | AQ27: 2024-04-22 | AR27: 2024-05-21 | AS27: Yes | AT27: Website | AU27: Amit Deshmukh | AV27: Active
A28: AU-027 | B28: Siya Desai | C28: 2006-04-22 | D28: Male | E28: 9816439415 | F28: siya.desai27@gmail.com | G28: 969, Aundh Pune | H28: Modern College | I28: 78 | J28: 9925998150 | K28: Crash Course | L28: 6 | M28: Afternoon | N28: 2024-02-02 | O28: 2024-07-31 | P28: R-114 | Q28: Online | R28: Tue-Thu-Sat | S28: Chemistry | T28: Sneha Patil | U28: 2024-03-16 | V28: 2024-03-14 | W28: 45981 | X28: 45836 | Y28: 145 | Z28: 3623 | AA28: Yes | AB28: =RANDBETWEEN(DATE(2025,7,1),DATE(2025,12,31)) -> 45912 | AC28: Partial | AD28: Cash | AE28: 8 | AF28: 74 | AG28: 94 | AH28: Needs Improvement | AI28: 63 | AJ28: 34 | AK28: 25 | AM28: 73 | AN28: No | AO28: 4 | AP28: 5 | AQ28: 2024-05-05 | AR28: 2024-06-04 | AS28: Yes | AT28: Facebook Ad | AU28: Nidhi Shah | AV28: Left | AW28: Switched institute
A29: AU-035 | B29: Ira Sharma | C29: 2006-03-25 | D29: Male | E29: 9861555077 | F29: ira.sharma35@gmail.com | G29: 102, Aundh Pune | H29: D.A.V. Public School | I29: 94 | J29: 9954095883 | K29: MHT-CET | L29: 3 | M29: Afternoon | N29: 2024-02-22 | O29: 2024-05-22 | P29: R-102 | Q29: Hybrid | R29: Mon-Wed-Fri | S29: Physics | T29: Anil Sharma | U29: 2024-04-11 | V29: 2024-04-09 | W29: 29344 | X29: 27076 | Y29: 2268 | Z29: 4754 | AA29: No | AB29: =RANDBETWEEN(DATE(2025,7,1),DATE(2025,12,31)) -> 45947 | AC29: Partial | AD29: Cash | AE29: 8 | AF29: 48 | AG29: 96 | AH29: Needs Improvement | AI29: 100 | AJ29: 60 | AK29: 44 | AL29: Sick leave | AM29: 73 | AN29: Yes | AO29: 4 | AP29: 2 | AQ29: 2024-05-20 | AR29: 2024-06-07 | AS29: Yes | AT29: Website | AU29: Rahul Mehta | AV29: Active
A30: AU-012 | B30: Kunal Godbole | C30: 2006-01-14 | D30: Female | E30: 9861968735 | F30: ayaan.sharma12@gmail.com | G30: 336, Aundh Pune | H30: City School | I30: 63 | J30: 9939854108 | K30: JEE | L30: 12 | M30: Evening | N30: 2024-02-27 | O30: 2025-02-21 | P30: R-112 | Q30: Online | R30: Mon-Wed-Fri | S30: Biology | T30: Vikram Joshi | U30: 2024-02-06 | V30: 2024-02-03 | W30: 47685 | X30: 47563 | Y30: 122 | Z30: 663 | AA30: No | AB30: =RANDBETWEEN(DATE(2025,7,1),DATE(2025,12,31)) -> 45844 | AC30: Partial | AD30: UPI | AE30: 9 | AF30: 76 | AG30: 78 | AH30: Needs Improvement | AI30: 98 | AJ30: 59 | AK30: 43 | AL30: Family function | AM30: 72 | AN30: No | AO30: 4 | AP30: 2 | AQ30: 2024-03-03 | AR30: 2024-03-13 | AS30: Yes | AT30: Website | AU30: Nidhi Shah | AV30: Left | AW30: Switched institute
A31: AU-013 | B31: Meera Patil | C31: 2005-12-01 | D31: Male | E31: 9817700186 | F31: meera.patil13@gmail.com | G31: 589, Aundh Pune | H31: D.A.V. Public School | I31: 71 | J31: 9931778745 | K31: MHT-CET | L31: 12 | M31: Morning | N31: 2024-01-24 | O31: 2025-01-18 | P31: R-112 | Q31: Online | R31: Mon-Wed-Fri | S31: Maths | T31: Ravi Kumar | U31: 2024-03-04 | V31: 2024-02-25 | W31: 19992 | X31: 16844 | Y31: 3148 | Z31: 3877 | AA31: Yes | AB31: =RANDBETWEEN(DATE(2025,7,1),DATE(2025,12,31)) -> 45885 | AC31: Partial | AD31: Bank Transfer | AE31: 6 | AF31: 82 | AG31: 99 | AH31: Needs Improvement | AI31: 73 | AJ31: 37 | AK31: 27 | AL31: Sick leave | AM31: 72 | AN31: Yes | AO31: 4 | AP31: 3 | AQ31: 2024-04-30 | AR31: 2024-05-28 | AS31: No | AT31: Instagram Ad | AU31: Nidhi Shah | AV31: Left | AW31: Too far
A32: AU-042 | B32: Ira Patil | C32: 2005-01-20 | D32: Male | E32: 9829100757 | F32: ira.patil42@gmail.com | G32: 450, Aundh Pune | H32: Spicer Higher Secondary School | I32: 76 | J32: 9993814827 | K32: Crash Course | L32: 3 | M32: Evening | N32: 2024-03-16 | O32: 2024-06-14 | P32: R-118 | Q32: Offline | R32: Mon-Wed-Fri | S32: Physics | T32: Vikram Joshi | U32: 2024-05-27 | V32: 2024-05-21 | W32: 41685 | X32: 41195 | Y32: 490 | Z32: 4889 | AA32: No | AB32: =RANDBETWEEN(DATE(2025,7,1),DATE(2025,12,31)) -> 45872 | AC32: Partial | AD32: UPI | AE32: 1 | AF32: 62 | AG32: 98 | AH32: Average | AI32: 67 | AJ32: 55 | AK32: 39 | AL32: Sick leave | AM32: 70 | AN32: No | AO32: 2 | AP32: 2 | AQ32: 2024-07-09 | AR32: 2024-08-08 | AS32: No | AT32: Instagram Ad | AU32: Nidhi Shah | AV32: Left | AW32: Switched institute
A33: AU-011 | B33: Riya Patil | C33: 2006-04-17 | D33: Male | E33: 9887840907 | F33: riya.patil11@gmail.com | G33: 792, Aundh Pune | H33: Spicer Higher Secondary School | I33: 66 | J33: 9932763392 | K33: JEE | L33: 6 | M33: Morning | N33: 2024-04-07 | O33: 2024-10-04 | P33: R-110 | Q33: Online | R33: Mon-Wed-Fri | S33: Physics | T33: Preeti Desai | U33: 2024-02-15 | V33: 2024-02-08 | W33: 20936 | X33: 18272 | Y33: 2664 | Z33: 2870 | AA33: No | AB33: =RANDBETWEEN(DATE(2025,7,1),DATE(2025,12,31)) -> 45860 | AC33: Partial | AD33: UPI | AE33: 10 | AF33: 49 | AG33: 76 | AH33: Average | AI33: 96 | AJ33: 38 | AK33: 25 | AM33: 65 | AN33: No | AO33: 1 | AP33: 5 | AQ33: 2024-03-10 | AR33: 2024-03-31 | AS33: Yes | AT33: Website | AU33: Amit Deshmukh | AV33: Left | AW33: Lost interest
A34: AU-032 | B34: Pranav Gadgil | C34: 2005-12-18 | D34: Male | E34: 9856821801 | F34: riya.joshi32@gmail.com | G34: 130, Aundh Pune | H34: Modern College | I34: 80 | J34: 9967122501 | K34: Foundation 8-10 | L34: 3 | M34: Morning | N34: 2024-04-04 | O34: 2024-07-03 | P34: R-117 | Q34: Offline | R34: Mon-Wed-Fri | S34: Maths | T34: Anil Sharma | U34: 2024-02-11 | V34: 2024-02-11 | W34: 47410 | X34: 46718 | Y34: 692 | Z34: 2379 | AA34: Yes | AB34: =RANDBETWEEN(DATE(2025,7,1),DATE(2025,12,31)) -> 45948 | AC34: Partial | AD34: Cash | AE34: 10 | AF34: 76 | AG34: 77 | AH34: Good | AI34: 88 | AJ34: 36 | AK34: 22 | AM34: 61 | AN34: Yes | AO34: 3 | AP34: 2 | AQ34: 2024-04-02 | AR34: 2024-05-02 | AS34: No | AT34: Referral | AU34: Amit Deshmukh | AV34: Left | AW34: Too far
A35: AU-022 | B35: Saurabh Ranade | C35: 2005-01-03 | D35: Male | E35: 9859987035 | F35: ayaan.kumar22@gmail.com | G35: 625, Aundh Pune | H35: Modern College | I35: 65 | J35: 9918907790 | K35: Foundation 8-10 | L35: 12 | M35: Morning | N35: 2024-02-25 | O35: 2025-02-19 | P35: R-106 | Q35: Online | R35: Mon-Wed-Fri | S35: Biology | T35: Anil Sharma | U35: 2024-03-13 | V35: 2024-03-11 | W35: 29550 | X35: 28618 | Y35: 932 | Z35: 3302 | AA35: Yes | AB35: =RANDBETWEEN(DATE(2025,7,1),DATE(2025,12,31)) -> 45942 | AC35: Partial | AD35: Bank Transfer | AE35: 8 | AF35: 45 | AG35: 54 | AH35: Good | AI35: 78 | AJ35: 38 | AK35: 23 | AL35: Family function | AM35: 60 | AN35: Yes | AO35: 3 | AP35: 1 | AQ35: 2024-05-10 | AR35: 2024-06-09 | AS35: No | AT35: Referral | AU35: Amit Deshmukh | AV35: Left | AW35: Switched institute
A36: AU-045 | B36: Riya Joshi | C36: 2005-08-15 | D36: Male | E36: 9837045769 | F36: riya.joshi45@gmail.com | G36: 968, Aundh Pune | H36: Modern College | I36: 63 | J36: 9990130107 | K36: Foundation 8-10 | L36: 6 | M36: Afternoon | N36: 2024-01-30 | O36: 2024-07-28 | P36: R-103 | Q36: Hybrid | R36: Tue-Thu-Sat | S36: Physics | T36: Ravi Kumar | U36: 2024-02-18 | V36: 2024-02-18 | W36: 19785 | X36: 18254 | Y36: 1531 | Z36: 2562 | AA36: No | AB36: =RANDBETWEEN(DATE(2025,7,1),DATE(2025,12,31)) -> 45862 | AC36: Partial | AD36: Card | AE36: 2 | AF36: 45 | AG36: 65 | AH36: Needs Improvement | AI36: 73 | AJ36: 37 | AK36: 22 | AL36: Sick leave | AM36: 59 | AN36: Yes | AO36: 4 | AP36: 1 | AQ36: 2024-03-14 | AR36: 2024-03-30 | AS36: Yes | AT36: Website | AU36: Rahul Mehta | AV36: Active
A37: AU-021 | B37: Aarav Kumar | C37: 2005-07-20 | D37: Female | E37: 9869774216 | F37: aarav.kumar21@gmail.com | G37: 513, Aundh Pune | H37: Spicer Higher Secondary School | I37: 65 | J37: 9919070144 | K37: NEET | L37: 3 | M37: Afternoon | N37: 2024-02-21 | O37: 2024-05-21 | P37: R-107 | Q37: Online | R37: Tue-Thu-Sat | S37: Biology | T37: Anil Sharma | U37: 2024-03-06 | V37: 2024-03-02 | W37: 32976 | X37: 32180 | Y37: 796 | Z37: 2727 | AA37: Yes | AB37: =RANDBETWEEN(DATE(2025,7,1),DATE(2025,12,31)) -> 45903 | AC37: Partial | AD37: Cash | AE37: 5 | AF37: 55 | AG37: 55 | AH37: Good | AI37: 63 | AJ37: 54 | AK37: 31 | AL37: Family function | AM37: 57 | AN37: No | AO37: 4 | AP37: 2 | AQ37: 2024-05-04 | AR37: 2024-06-03 | AS37: Yes | AT37: Instagram Ad | AU37: Rahul Mehta | AV37: Active
A38: AU-034 | B38: Ayaan Joshi | C38: 2005-08-05 | D38: Female | E38: 9858291899 | F38: ayaan.joshi34@gmail.com | G38: 776, Aundh Pune | H38: Vidyanchal School | I38: 69 | J38: 9924142404 | K38: Crash Course | L38: 12 | M38: Evening | N38: 2024-02-13 | O38: 2025-02-07 | P38: R-111 | Q38: Offline | R38: Tue-Thu-Sat | S38: Physics | T38: Vikram Joshi | U38: 2024-05-02 | V38: 2024-04-22 | W38: 28619 | X38: 25381 | Y38: 3238 | Z38: 3240 | AA38: No | AB38: =RANDBETWEEN(DATE(2025,7,1),DATE(2025,12,31)) -> 45963 | AC38: Partial | AD38: Bank Transfer | AE38: 6 | AF38: 85 | AG38: 88 | AH38: Needs Improvement | AI38: 83 | AJ38: 26 | AK38: 15 | AL38: Family function | AM38: 57 | AN38: No | AO38: 5 | AP38: 4 | AQ38: 2024-06-01 | AR38: 2024-07-01 | AS38: Yes | AT38: Walk-in | AU38: Rahul Mehta | AV38: Left | AW38: Switched institute
A39: AU-050 | B39: Aarav Sharma | C39: 2006-05-20 | D39: Male | E39: 9892575113 | F39: aarav.sharma50@gmail.com | G39: 160, Aundh Pune | H39: D.A.V. Public School | I39: 83 | J39: 9949987246 | K39: JEE | L39: 3 | M39: Evening | N39: 2024-02-06 | O39: 2024-05-06 | P39: R-108 | Q39: Offline | R39: Tue-Thu-Sat | S39: Chemistry | T39: Ravi Kumar | U39: 2024-03-18 | V39: 2024-03-14 | W39: 38119 | X39: 38089 | Y39: 30 | Z39: 878 | AA39: Yes | AB39: =RANDBETWEEN(DATE(2025,7,1),DATE(2025,12,31)) -> 45959 | AC39: Partial | AD39: Card | AE39: 5 | AF39: 49 | AG39: 86 | AH39: Good | AI39: 62 | AJ39: 33 | AK39: 19 | AL39: Family function | AM39: 57 | AN39: No | AO39: 4 | AP39: 1 | AQ39: 2024-04-26 | AR39: 2024-05-24 | AS39: No | AT39: Instagram Ad | AU39: Amit Deshmukh | AV39: Active
A40: AU-039 | B40: Anaya Sharma | C40: 2005-06-08 | D40: Female | E40: 9832258449 | F40: anaya.sharma39@gmail.com | G40: 746, Aundh Pune | H40: City International School | I40: 82 | J40: 9990085925 | K40: Foundation 8-10 | L40: 12 | M40: Evening | N40: 2024-01-12 | O40: 2025-01-06 | P40: R-103 | Q40: Online | R40: Tue-Thu-Sat | S40: Physics | T40: Sneha Patil | U40: 2024-03-01 | V40: 2024-02-26 | W40: 39856 | X40: 38099 | Y40: 1757 | Z40: 4355 | AA40: Yes | AB40: =RANDBETWEEN(DATE(2025,7,1),DATE(2025,12,31)) -> 45958 | AC40: Partial | AD40: Bank Transfer | AE40: 3 | AF40: 54 | AG40: 62 | AH40: Average | AI40: 80 | AJ40: 35 | AK40: 19 | AL40: Sick leave | AM40: 54 | AN40: Yes | AO40: 5 | AP40: 3 | AQ40: 2024-04-22 | AR40: 2024-05-20 | AS40: No | AT40: Referral | AU40: Nidhi Shah | AV40: Left | AW40: Lost interest
...

Sheet Master Sheet
A1: Student ID | B1: Student Name | C1: Date of Birth | D1: Gender | E1: Parent Contact Number | F1: Student Email | G1: Address | H1: School/College Name | I1: Previous Academic Performance (%) | J1: Emergency Contact | K1: Course | L1: Course Duration (Months) | M1: Batch | N1: Batch Start Date | O1: Batch End Date | P1: Classroom/Room No. | Q1: Mode | R1: Session Days | S1: Subject | T1: Teacher | U1: Enrollment Date | V1: Registration Date | W1: Total Course Fees | X1: Amount Paid | Y1: Pending Amount | Z1: Discount Given | AA1: Installment Plan | AB1: Next Payment Due Date | AC1: Payment Status | AD1: Payment Method | AE1: Number of Tests Taken | AF1: Average Test Score | AG1: Top Test Score | AH1: Progress Comments | AI1: Homework Completion Rate (%) | AJ1: Total Classes Conducted | AK1: Classes Attended | AL1: Leave Notes/Remarks | AM1: Attendance (%) | AN1: Attendance Alerts Sent | AO1: Parent Feedback | AP1: Student Feedback | AQ1: Last Feedback Date | AR1: Follow-up Date | AS1: WhatsApp Opt-in | AT1: Lead Source | AU1: Counselor/Admission Handled By | AV1: Dropout Status | AW1: Reason for Leaving | AX1: Branch
A2: AU-007 | B2: Aarav Patil | C2: 2006-05-20 | D2: Female | E2: 9827095765 | F2: ira.sharma7@gmail.com | G2: atul apts, aundh, pune | H2: City International School | I2: 82 | J2: 9953297386 | K2: Foundation 8-10 | L2: 6 | M2: Evening | N2: 2024-01-28 | O2: 2024-07-26 | P2: R-111 | Q2: Offline | R2: Tue-Thu-Sat | S2: Maths | T2: Preeti Desai | U2: 2024-05-20 | V2: 2024-05-15 | W2: 43018 | X2: 39256 | Y2: 3762 | Z2: 4189 | AA2: No | AB2: =RANDBETWEEN(DATE(2025,7,1),DATE(2025,12,31)) -> 45872 | AC2: Partial | AD2: UPI | AE2: 5 | AF2: 41 | AG2: 77 | AH2: Average | AI2: 81 | AJ2: 24 | AK2: 24 | AL2: Family function | AM2: 100 | AN2: Yes | AO2: 3 | AP2: 5 | AQ2: 2024-07-11 | AR2: 2024-08-09 | AS2: No | AT2: Facebook Ad | AU2: Nidhi Shah | AV2: Left | AW2: Switched institute | AX2: =IF(LEFT(A2,2)="AU","Aundh",IF(LEFT(A2,2)="KO","Kondhwa","Sinhgad Road")) -> Aundh
A3: AU-048 | B3: Atharva Deshmukh | C3: 2006-07-29 | D3: Female | E3: 9895313505 | F3: aarav.kumar48@gmail.com | G3: 937, Aundh Pune | H3: Modern College | I3: 87 | J3: 9912189875 | K3: Foundation 8-10 | L3: 3 | M3: Afternoon | N3: 2024-01-15 | O3: 2024-04-14 | P3: R-118 | Q3: Offline | R3: Mon-Wed-Fri | S3: Physics | T3: Ravi Kumar | U3: 2024-04-01 | V3: 2024-03-25 | W3: 20086 | X3: 19800 | Y3: 286 | Z3: 1952 | AA3: No | AB3: =RANDBETWEEN(DATE(2025,7,1),DATE(2025,12,31)) -> 46011 | AC3: Partial | AD3: Bank Transfer | AE3: 9 | AF3: 67 | AG3: 86 | AH3: Good | AI3: 67 | AJ3: 22 | AK3: 22 | AM3: 100 | AN3: No | AO3: 5 | AP3: 4 | AQ3: 2024-04-23 | AR3: 2024-05-06 | AS3: No | AT3: Instagram Ad | AU3: Amit Deshmukh | AV3: Left | AW3: Too far | AX3: =IF(LEFT(A3,2)="AU","Aundh",IF(LEFT(A3,2)="KO","Kondhwa","Sinhgad Road")) -> Aundh
A4: AU-015 | B4: aryan patil | C4: 2006-07-12 | D4: Female | E4: 9827032133 | F4: aarav.patil15@gmail.com | G4: 694, Aundh Pune | H4: Vidyanchal School | I4: 79 | J4: 9919617248 | K4: NEET | L4: 6 | M4: Morning | N4: 2024-01-23 | O4: 2024-07-21 | P4: R-107 | Q4: Hybrid | R4: Mon-Wed-Fri | S4: Chemistry | T4: Sneha Patil | U4: 2024-02-08 | V4: 2024-02-06 | W4: 33714 | X4: 33476 | Y4: 238 | Z4: 1249 | AA4: Yes | AB4: =RANDBETWEEN(DATE(2025,7,1),DATE(2025,12,31)) -> 45883 | AC4: Partial | AD4: Bank Transfer | AE4: 8 | AF4: 66 | AG4: 79 | AH4: Needs Improvement | AI4: 85 | AJ4: 51 | AK4: 50 | AM4: 100 | AN4: No | AO4: 2 | AP4: 5 | AQ4: 2024-03-01 | AR4: 2024-03-14 | AS4: No | AT4: Website | AU4: Amit Deshmukh | AV4: Left | AW4: Switched institute | AX4: =IF(LEFT(A4,2)="AU","Aundh",IF(LEFT(A4,2)="KO","Kondhwa","Sinhgad Road")) -> Aundh
A5: AU-044 | B5: Kabir Desai | C5: 2005-09-24 | D5: Male | E5: 9861278670 | F5: kabir.desai44@gmail.com | G5: 169, Aundh Pune | H5: D.A.V. Public School | I5: 70 | J5: 9926091051 | K5: MHT-CET | L5: 6 | M5: Morning | N5: 2024-02-11 | O5: 2024-08-09 | P5: R-120 | Q5: Hybrid | R5: Tue-Thu-Sat | S5: Chemistry | T5: Anil Sharma | U5: 2024-04-12 | V5: 2024-04-09 | W5: 26521 | X5: 25742 | Y5: 779 | Z5: 1089 | AA5: No | AB5: =RANDBETWEEN(DATE(2025,7,1),DATE(2025,12,31)) -> 45909 | AC5: Partial | AD5: UPI | AE5: 7 | AF5: 79 | AG5: 79 | AH5: Good | AI5: 78 | AJ5: 36 | AK5: 35 | AM5: 97 | AN5: Yes | AO5: 5 | AP5: 1 | AQ5: 2024-05-08 | AR5: 2024-05-31 | AS5: Yes | AT5: Instagram Ad | AU5: Amit Deshmukh | AV5: Left | AW5: Lost interest | AX5: =IF(LEFT(A5,2)="AU","Aundh",IF(LEFT(A5,2)="KO","Kondhwa","Sinhgad Road")) -> Aundh
A6: AU-017 | B6: Vivaan Kulkarni | C6: 2005-06-15 | D6: Female | E6: 9810220839 | F6: anaya.joshi17@gmail.com | G6: 751, Aundh Pune | H6: City School | I6: 75 | J6: 9963948363 | K6: NEET | L6: 12 | M6: Morning | N6: 2024-01-20 | O6: 2025-01-14 | P6: R-104 | Q6: Offline | R6: Tue-Thu-Sat | S6: Physics | T6: Anil Sharma | U6: 2024-02-24 | V6: 2024-02-24 | W6: 41229 | X6: 40571 | Y6: 658 | Z6: 4623 | AA6: Yes | AB6: =RANDBETWEEN(DATE(2025,7,1),DATE(2025,12,31)) -> 45948 | AC6: Partial | AD6: Bank Transfer | AE6: 6 | AF6: 41 | AG6: 93 | AH6: Needs Improvement | AI6: 85 | AJ6: 33 | AK6: 32 | AM6: 96 | AN6: Yes | AO6: 1 | AP6: 1 | AQ6: 2024-03-26 | AR6: 2024-04-21 | AS6: Yes | AT6: Instagram Ad | AU6: Rahul Mehta | AV6: Left | AW6: Switched institute | AX6: =IF(LEFT(A6,2)="AU","Aundh",IF(LEFT(A6,2)="KO","Kondhwa","Sinhgad Road")) -> Aundh
A7: AU-001 | B7: Reyansh Sharma | C7: 2005-01-18 | D7: Female | E7: 9855426302 | F7: reyansh.sharma1@gmail.com | G7: 463, Aundh Pune | H7: Vidyanchal School | I7: 77 | J7: 9926479089 | K7: Foundation 8-10 | L7: 12 | M7: Evening | N7: 2024-01-02 | O7: 2024-12-27 | P7: R-113 | Q7: Hybrid | R7: Tue-Thu-Sat | S7: Maths | T7: Preeti Desai | U7: 2024-04-20 | V7: 2024-04-14 | W7: 42851 | X7: 40171 | Y7: 2680 | Z7: 4474 | AA7: No | AB7: =RANDBETWEEN(DATE(2025,7,1),DATE(2025,12,31)) -> 45849 | AC7: Partial | AD7: Card | AE7: 1 | AF7: 46 | AG7: 96 | AH7: Average | AI7: 71 | AJ7: 45 | AK7: 43 | AM7: 95 | AN7: No | AO7: 2 | AP7: 4 | AQ7: 2024-05-14 | AR7: 2024-06-08 | AS7: No | AT7: Referral | AU7: Amit Deshmukh | AV7: Left | AW7: Lost interest | AX7: =IF(LEFT(A7,2)="AU","Aundh",IF(LEFT(A7,2)="KO","Kondhwa","Sinhgad Road")) -> Aundh
A8: AU-030 | B8: Siddharth Joshi | C8: 2005-04-23 | D8: Male | E8: 9895766321 | F8: aarav.desai30@gmail.com | G8: 870, Aundh Pune | H8: D.A.V. Public School | I8: 94 | J8: 9975991785 | K8: NEET | L8: 3 | M8: Afternoon | N8: 2024-01-06 | O8: 2024-04-05 | P8: R-120 | Q8: Online | R8: Mon-Wed-Fri | S8: Maths | T8: Vikram Joshi | U8: 2024-02-24 | V8: 2024-02-15 | W8: 21243 | X8: 20076 | Y8: 1167 | Z8: 3153 | AA8: Yes | AB8: =RANDBETWEEN(DATE(2025,7,1),DATE(2025,12,31)) -> 45958 | AC8: Partial | AD8: Cash | AE8: 2 | AF8: 67 | AG8: 70 | AH8: Needs Improvement | AI8: 82 | AJ8: 60 | AK8: 57 | AL8: Family function | AM8: 95 | AN8: Yes | AO8: 5 | AP8: 4 | AQ8: 2024-04-03 | AR8: 2024-04-21 | AS8: Yes | AT8: Walk-in | AU8: Rahul Mehta | AV8: Active | AX8: =IF(LEFT(A8,2)="AU","Aundh",IF(LEFT(A8,2)="KO","Kondhwa","Sinhgad Road")) -> Aundh
A9: AU-014 | B9: Anay Shinde | C9: 2006-06-06 | D9: Male | E9: 9822011112 | F9: vivaan.joshi14@gmail.com | G9: 738, Aundh Pune | H9: Modern College | I9: 62 | J9: 9953143872 | K9: JEE | L9: 12 | M9: Morning | N9: 2024-03-22 | O9: 2025-03-17 | P9: R-114 | Q9: Online | R9: Tue-Thu-Sat | S9: Biology | T9: Anil Sharma | U9: 2024-02-25 | V9: 2024-02-25 | W9: 24474 | X9: 20873 | Y9: 3601 | Z9: 4292 | AA9: No | AB9: =RANDBETWEEN(DATE(2025,7,1),DATE(2025,12,31)) -> 45968 | AC9: Partial | AD9: Card | AE9: 6 | AF9: 44 | AG9: 50 | AH9: Needs Improvement | AI9: 91 | AJ9: 34 | AK9: 32 | AM9: 94 | AN9: No | AO9: 2 | AP9: 1 | AQ9: 2024-03-16 | AR9: 2024-04-06 | AS9: No | AT9: Walk-in | AU9: Nidhi Shah | AV9: Active | AX9: =IF(LEFT(A9,2)="AU","Aundh",IF(LEFT(A9,2)="KO","Kondhwa","Sinhgad Road")) -> Aundh
A10: AU-018 | B10: Ishaan Chavan | C10: 2005-05-10 | D10: Male | E10: 9864434821 | F10: anaya.kumar18@gmail.com | G10: 551, Aundh Pune | H10: Modern College | I10: 71 | J10: 9951130048 | K10: NEET | L10: 12 | M10: Morning | N10: 2024-01-05 | O10: 2024-12-30 | P10: R-101 | Q10: Hybrid | R10: Tue-Thu-Sat | S10: Biology | T10: Anil Sharma | U10: 2024-03-06 | V10: 2024-03-05 | W10: 29689 | X10: 28607 | Y10: 1082 | Z10: 1301 | AA10: Yes | AB10: =RANDBETWEEN(DATE(2025,7,1),DATE(2025,12,31)) -> 45903 | AC10: Partial | AD10: Card | AE10: 4 | AF10: 54 | AG10: 74 | AH10: Needs Improvement | AI10: 90 | AJ10: 56 | AK10: 53 | AL10: Family function | AM10: 94 | AN10: Yes | AO10: 2 | AP10: 5 | AQ10: 2024-04-17 | AR10: 2024-05-15 | AS10: No | AT10: Instagram Ad | AU10: Amit Deshmukh | AV10: Left | AW10: Too far | AX10: =IF(LEFT(A10,2)="AU","Aundh",IF(LEFT(A10,2)="KO","Kondhwa","Sinhgad Road")) -> Aundh
A11: AU-020 | B11: Ira Joshi | C11: 2006-01-28 | D11: Male | E11: 9898616022 | F11: ira.joshi20@gmail.com | G11: 236, Aundh Pune | H11: Modern College | I11: 67 | J11: 9921755464 | K11: JEE | L11: 3 | M11: Morning | N11: 2024-03-03 | O11: 2024-06-01 | P11: R-109 | Q11: Online | R11: Tue-Thu-Sat | S11: Chemistry | T11: Anil Sharma | U11: 2024-03-12 | V11: 2024-03-10 | W11: 15521 | X11: 15338 | Y11: 183 | Z11: 1968 | AA11: No | AB11: =RANDBETWEEN(DATE(2025,7,1),DATE(2025,12,31)) -> 45948 | AC11: Partial | AD11: Bank Transfer | AE11: 5 | AF11: 81 | AG11: 87 | AH11: Average | AI11: 77 | AJ11: 56 | AK11: 53 | AL11: Sick leave | AM11: 94 | AN11: Yes | AO11: 2 | AP11: 4 | AQ11: 2024-04-25 | AR11: 2024-05-05 | AS11: No | AT11: Website | AU11: Amit Deshmukh | AV11: Left | AW11: Switched institute | AX11: =IF(LEFT(A11,2)="AU","Aundh",IF(LEFT(A11,2)="KO","Kondhwa","Sinhgad Road")) -> Aundh
A12: AU-047 | B12: Omkar Bhosale | C12: 2005-11-14 | D12: Male | E12: 9886591060 | F12: riya.patil47@gmail.com | G12: 113, Aundh Pune | H12: Vidyanchal School | I12: 76 | J12: 9978630854 | K12: JEE | L12: 6 | M12: Morning | N12: 2024-04-04 | O12: 2024-10-01 | P12: R-111 | Q12: Hybrid | R12: Mon-Wed-Fri | S12: Physics | T12: Vikram Joshi | U12: 2024-02-12 | V12: 2024-02-02 | W12: 47666 | X12: 47504 | Y12: 162 | Z12: 365 | AA12: Yes | AB12: =RANDBETWEEN(DATE(2025,7,1),DATE(2025,12,31)) -> 45925 | AC12: Partial | AD12: Bank Transfer | AE12: 6 | AF12: 73 | AG12: 82 | AH12: Good | AI12: 75 | AJ12: 25 | AK12: 23 | AL12: Family function | AM12: 92 | AN12: Yes | AO12: 4 | AP12: 3 | AQ12: 2024-03-15 | AR12: 2024-04-01 | AS12: No | AT12: Walk-in | AU12: Amit Deshmukh | AV12: Left | AW12: Too far | AX12: =IF(LEFT(A12,2)="AU","Aundh",IF(LEFT(A12,2)="KO","Kondhwa","Sinhgad Road")) -> Aundh
A13: AU-028 | B13: Rudra Gaikwad | C13: 2006-06-28 | D13: Female | E13: 9814694076 | F13: meera.joshi28@gmail.com | G13: 113, Aundh Pune | H13: Modern College | I13: 84 | J13: 9969698577 | K13: JEE | L13: 12 | M13: Morning | N13: 2024-01-11 | O13: 2025-01-05 | P13: R-102 | Q13: Hybrid | R13: Mon-Wed-Fri | S13: Physics | T13: Vikram Joshi | U13: 2024-02-11 | V13: 2024-02-04 | W13: 31688 | X13: 31188 | Y13: 500 | Z13: 1442 | AA13: No | AB13: =RANDBETWEEN(DATE(2025,7,1),DATE(2025,12,31)) -> 45895 | AC13: Partial | AD13: Cash | AE13: 10 | AF13: 71 | AG13: 91 | AH13: Good | AI13: 80 | AJ13: 24 | AK13: 22 | AM13: 91 | AN13: No | AO13: 3 | AP13: 3 | AQ13: 2024-04-05 | AR13: 2024-05-01 | AS13: Yes | AT13: Instagram Ad | AU13: Amit Deshmukh | AV13: Left | AW13: Too far | AX13: =IF(LEFT(A13,2)="AU","Aundh",IF(LEFT(A13,2)="KO","Kondhwa","Sinhgad Road")) -> Aundh
A14: AU-043 | B14: Vedant Jadhav | C14: 2005-05-30 | D14: Male | E14: 9827525677 | F14: ayaan.joshi43@gmail.com | G14: 318, Aundh Pune | H14: Spicer Higher Secondary School | I14: 93 | J14: 9973127650 | K14: Foundation 8-10 | L14: 3 | M14: Morning | N14: 2024-03-23 | O14: 2024-06-21 | P14: R-116 | Q14: Hybrid | R14: Mon-Wed-Fri | S14: Physics | T14: Sneha Patil | U14: 2024-03-18 | V14: 2024-03-18 | W14: 33476 | X14: 32565 | Y14: 911 | Z14: 922 | AA14: Yes | AB14: =RANDBETWEEN(DATE(2025,7,1),DATE(2025,12,31)) -> 45963 | AC14: Partial | AD14: Bank Transfer | AE14: 8 | AF14: 50 | AG14: 75 | AH14: Good | AI14: 94 | AJ14: 37 | AK14: 34 | AL14: Sick leave | AM14: 100 | AN14: Yes | AO14: 1 | AP14: 4 | AQ14: 2024-04-19 | AR14: 2024-04-29 | AS14: Yes | AT14: Website | AU14: Rahul Mehta | AV14: Left | AW14: Lost interest | AX14: =IF(LEFT(A14,2)="AU","Aundh",IF(LEFT(A14,2)="KO","Kondhwa","Sinhgad Road")) -> Aundh
A15: AU-031 | B15: Vivaan Joshi | C15: 2005-04-09 | D15: Male | E15: 9885303785 | F15: vivaan.joshi31@gmail.com | G15: 460, Aundh Pune | H15: City International School | I15: 75 | J15: 9990322781 | K15: Foundation 8-10 | L15: 12 | M15: Evening | N15: 2024-02-15 | O15: 2025-02-09 | P15: R-103 | Q15: Hybrid | R15: Tue-Thu-Sat | S15: Chemistry | T15: Preeti Desai | U15: 2024-02-17 | V15: 2024-02-14 | W15: 42334 | X15: 40547 | Y15: 1787 | Z15: 4132 | AA15: Yes | AB15: =RANDBETWEEN(DATE(2025,7,1),DATE(2025,12,31)) -> 46022 | AC15: Partial | AD15: Bank Transfer | AE15: 7 | AF15: 53 | AG15: 85 | AH15: Average | AI15: 98 | AJ15: 20 | AK15: 18 | AM15: 90 | AN15: No | AO15: 3 | AP15: 5 | AQ15: 2024-03-30 | AR15: 2024-04-26 | AS15: Yes | AT15: Walk-in | AU15: Nidhi Shah | AV15: Left | AW15: Lost interest | AX15: =IF(LEFT(A15,2)="AU","Aundh",IF(LEFT(A15,2)="KO","Kondhwa","Sinhgad Road")) -> Aundh
A16: AU-006 | B16: Meera Desai | C16: 2006-05-16 | D16: Male | E16: 9820367740 | F16: meera.desai6@gmail.com | G16: 368, Aundh Pune | H16: Spicer Higher Secondary School | I16: 89 | J16: 9952336944 | K16: MHT-CET | L16: 3 | M16: Morning | N16: 2024-03-12 | O16: 2024-06-10 | P16: R-120 | Q16: Offline | R16: Mon-Wed-Fri | S16: Biology | T16: Preeti Desai | U16: 2024-03-06 | V16: 2024-02-28 | W16: 40557 | X16: 40142 | Y16: 415 | Z16: 1522 | AA16: Yes | AB16: =RANDBETWEEN(DATE(2025,7,1),DATE(2025,12,31)) -> 45999 | AC16: Partial | AD16: Cash | AE16: 4 | AF16: 69 | AG16: 93 | AH16: Good | AI16: 61 | AJ16: 52 | AK16: 46 | AL16: Family function | AM16: 88 | AN16: No | AO16: 2 | AP16: 2 | AQ16: 2024-03-27 | AR16: 2024-04-22 | AS16: Yes | AT16: Facebook Ad | AU16: Rahul Mehta | AV16: Active | AX16: =IF(LEFT(A16,2)="AU","Aundh",IF(LEFT(A16,2)="KO","Kondhwa","Sinhgad Road")) -> Aundh
A17: AU-033 | B17: Kabir Patil | C17: 2005-06-09 | D17: Male | E17: 9845974289 | F17: kabir.patil33@gmail.com | G17: 395, Aundh Pune | H17: Modern College | I17: 93 | J17: 9934055823 | K17: MHT-CET | L17: 3 | M17: Morning | N17: 2024-02-01 | O17: 2024-05-01 | P17: R-112 | Q17: Online | R17: Mon-Wed-Fri | S17: Biology | T17: Vikram Joshi | U17: 2024-02-21 | V17: 2024-02-11 | W17: 21123 | X17: 20086 | Y17: 1037 | Z17: 2663 | AA17: No | AB17: =RANDBETWEEN(DATE(2025,7,1),DATE(2025,12,31)) -> 45841 | AC17: Partial | AD17: UPI | AE17: 2 | AF17: 40 | AG17: 68 | AH17: Good | AI17: 97 | AJ17: 48 | AK17: 42 | AL17: Sick leave | AM17: 87 | AN17: No | AO17: 5 | AP17: 1 | AQ17: 2024-04-05 | AR17: 2024-04-27 | AS17: No | AT17: Instagram Ad | AU17: Nidhi Shah | AV17: Left | AW17: Switched institute | AX17: =IF(LEFT(A17,2)="AU","Aundh",IF(LEFT(A17,2)="KO","Kondhwa","Sinhgad Road")) -> Aundh
A18: AU-024 | B18: Meera Sharma | C18: 2006-02-20 | D18: Male | E18: 9871747241 | F18: meera.sharma24@gmail.com | G18: 209, Aundh Pune | H18: Modern College | I18: 67 | J18: 9937156335 | K18: MHT-CET | L18: 3 | M18: Morning | N18: 2024-02-19 | O18: 2024-05-19 | P18: R-103 | Q18: Hybrid | R18: Tue-Thu-Sat | S18: Maths | T18: Preeti Desai | U18: 2024-05-10 | V18: 2024-05-09 | W18: 36359 | X18: 34507 | Y18: 1852 | Z18: 2266 | AA18: Yes | AB18: =RANDBETWEEN(DATE(2025,7,1),DATE(2025,12,31)) -> 45879 | AC18: Partial | AD18: Bank Transfer | AE18: 4 | AF18: 48 | AG18: 54 | AH18: Average | AI18: 72 | AJ18: 23 | AK18: 20 | AL18: Sick leave | AM18: 86 | AN18: No | AO18: 1 | AP18: 4 | AQ18: 2024-07-09 | AR18: 2024-08-03 | AS18: Yes | AT18: Instagram Ad | AU18: Nidhi Shah | AV18: Left | AW18: Lost interest | AX18: =IF(LEFT(A18,2)="AU","Aundh",IF(LEFT(A18,2)="KO","Kondhwa","Sinhgad Road")) -> Aundh
A19: AU-019 | B19: Aarav Desai | C19: 2006-02-07 | D19: Male | E19: 9888818798 | F19: aarav.desai19@gmail.com | G19: 894, Aundh Pune | H19: City International School | I19: 70 | J19: 9941695896 | K19: MHT-CET | L19: 12 | M19: Evening | N19: 2024-03-25 | O19: 2025-03-20 | P19: R-107 | Q19: Offline | R19: Mon-Wed-Fri | S19: Maths | T19: Sneha Patil | U19: 2024-04-27 | V19: 2024-04-26 | W19: 17919 | X19: 17530 | Y19: 389 | Z19: 511 | AA19: Yes | AB19: =RANDBETWEEN(DATE(2025,7,1),DATE(2025,12,31)) -> 45994 | AC19: Partial | AD19: Bank Transfer | AE19: 8 | AF19: 53 | AG19: 86 | AH19: Good | AI19: 82 | AJ19: 28 | AK19: 24 | AL19: Sick leave | AM19: 85 | AN19: Yes | AO19: 2 | AP19: 3 | AQ19: 2024-06-10 | AR19: 2024-07-03 | AS19: No | AT19: Instagram Ad | AU19: Nidhi Shah | AV19: Active | AX19: =IF(LEFT(A19,2)="AU","Aundh",IF(LEFT(A19,2)="KO","Kondhwa","Sinhgad Road")) -> Aundh
A20: AU-010 | B20: Vivaan Patil | C20: 2006-04-24 | D20: Male | E20: 9852635954 | F20: vivaan.patil10@gmail.com | G20: 189, Aundh Pune | H20: Vidyanchal School | I20: 64 | J20: 9951085984 | K20: Foundation 8-10 | L20: 3 | M20: Evening | N20: 2024-03-16 | O20: 2024-06-14 | P20: R-108 | Q20: Online | R20: Mon-Wed-Fri | S20: English | T20: Vikram Joshi | U20: 2024-05-08 | V20: 2024-05-08 | W20: 43563 | X20: 43281 | Y20: 282 | Z20: 3482 | AA20: Yes | AB20: =RANDBETWEEN(DATE(2025,7,1),DATE(2025,12,31)) -> 45918 | AC20: Partial | AD20: Bank Transfer | AE20: 9 | AF20: 81 | AG20: 91 | AH20: Needs Improvement | AI20: 97 | AJ20: 28 | AK20: 23 | AL20: Family function | AM20: 82 | AN20: No | AO20: 4 | AP20: 4 | AQ20: 2024-06-03 | AR20: 2024-06-14 | AS20: No | AT20: Website | AU20: Nidhi Shah | AV20: Active | AX20: =IF(LEFT(A20,2)="AU","Aundh",IF(LEFT(A20,2)="KO","Kondhwa","Sinhgad Road")) -> Aundh
A21: AU-002 | B21: manish sisodia | C21: 2005-09-11 | D21: Female | E21: 9856784978 | F21: aarav.kumar2@gmail.com | G21: 445, Aundh Pune | H21: City School | I21: 73 | J21: 9982991179 | K21: Foundation 8-10 | L21: 6 | M21: Morning | N21: 2024-01-15 | O21: 2024-07-13 | P21: R-102 | Q21: Hybrid | R21: Tue-Thu-Sat | S21: Maths | T21: Preeti Desai | U21: 2024-04-18 | V21: 2024-04-12 | W21: 27267 | X21: 25250 | Y21: 2017 | Z21: 3626 | AA21: No | AB21: =RANDBETWEEN(DATE(2025,7,1),DATE(2025,12,31)) -> 45936 | AC21: Partial | AD21: Bank Transfer | AE21: 6 | AF21: 75 | AG21: 77 | AH21: Good | AI21: 94 | AJ21: 21 | AK21: 17 | AL21: Family function | AM21: 80 | AN21: Yes | AO21: 3 | AP21: 4 | AQ21: 2024-05-08 | AR21: 2024-05-27 | AS21: No | AT21: Instagram Ad | AU21: Amit Deshmukh | AV21: Left | AW21: Switched institute | AX21: =IF(LEFT(A21,2)="AU","Aundh",IF(LEFT(A21,2)="KO","Kondhwa","Sinhgad Road")) -> Aundh
A22: AU-026 | B22: Kabir Joshi | C22: 2005-10-12 | D22: Male | E22: 9839141596 | F22: kabir.joshi26@gmail.com | G22: 681, Aundh Pune | H22: Modern College | I22: 92 | J22: 9967762687 | K22: JEE | L22: 3 | M22: Evening | N22: 2024-02-24 | O22: 2024-05-24 | P22: R-110 | Q22: Online | R22: Tue-Thu-Sat | S22: Chemistry | T22: Preeti Desai | U22: 2024-05-26 | V22: 2024-05-18 | W22: 38039 | X22: 34261 | Y22: 3778 | Z22: 4859 | AA22: No | AB22: =RANDBETWEEN(DATE(2025,7,1),DATE(2025,12,31)) -> 45992 | AC22: Partial | AD22: Cash | AE22: 8 | AF22: 49 | AG22: 68 | AH22: Needs Improvement | AI22: 84 | AJ22: 51 | AK22: 41 | AM22: 80 | AN22: No | AO22: 3 | AP22: 5 | AQ22: 2024-07-21 | AR22: 2024-08-15 | AS22: Yes | AT22: Walk-in | AU22: Rahul Mehta | AV22: Active | AX22: =IF(LEFT(A22,2)="AU","Aundh",IF(LEFT(A22,2)="KO","Kondhwa","Sinhgad Road")) -> Aundh
A23: AU-003 | B23: Tejas Pawar | C23: 2006-06-27 | D23: Male | E23: 9847094337 | F23: riya.joshi3@gmail.com | G23: 723, Aundh Pune | H23: City School | I23: 61 | J23: 9967496922 | K23: Crash Course | L23: 6 | M23: Afternoon | N23: 2024-01-22 | O23: 2024-07-20 | P23: R-119 | Q23: Offline | R23: Tue-Thu-Sat | S23: Biology | T23: Vikram Joshi | U23: 2024-05-28 | V23: 2024-05-19 | W23: 29239 | X23: 28279 | Y23: 960 | Z23: 1156 | AA23: No | AB23: =RANDBETWEEN(DATE(2025,7,1),DATE(2025,12,31)) -> 45976 | AC23: Partial | AD23: Cash | AE23: 5 | AF23: 63 | AG23: 64 | AH23: Average | AI23: 68 | AJ23: 54 | AK23: 43 | AL23: Sick leave | AM23: 79 | AN23: Yes | AO23: 1 | AP23: 5 | AQ23: 2024-07-11 | AR23: 2024-07-27 | AS23: Yes | AT23: Website | AU23: Nidhi Shah | AV23: Left | AW23: Switched institute | AX23: =IF(LEFT(A23,2)="AU","Aundh",IF(LEFT(A23,2)="KO","Kondhwa","Sinhgad Road")) -> Aundh
A24: AU-016 | B24: Anaya Joshi | C24: 2006-08-04 | D24: Male | E24: 9883268727 | F24: anaya.joshi16@gmail.com | G24: 245, Aundh Pune | H24: Modern College | I24: 90 | J24: 9982569341 | K24: Foundation 8-10 | L24: 3 | M24: Afternoon | N24: 2024-01-08 | O24: 2024-04-07 | P24: R-110 | Q24: Hybrid | R24: Tue-Thu-Sat | S24: English | T24: Sneha Patil | U24: 2024-04-13 | V24: 2024-04-11 | W24: 30207 | X24: 28610 | Y24: 1597 | Z24: 1889 | AA24: Yes | AB24: =RANDBETWEEN(DATE(2025,7,1),DATE(2025,12,31)) -> 45985 | AC24: Partial | AD24: Bank Transfer | AE24: 7 | AF24: 52 | AG24: 87 | AH24: Average | AI24: 72 | AJ24: 50 | AK24: 39 | AM24: 78 | AN24: Yes | AO24: 4 | AP24: 3 | AQ24: 2024-05-30 | AR24: 2024-06-25 | AS24: Yes | AT24: Website | AU24: Amit Deshmukh | AV24: Left | AW24: Lost interest | AX24: =IF(LEFT(A24,2)="AU","Aundh",IF(LEFT(A24,2)="KO","Kondhwa","Sinhgad Road")) -> Aundh
A25: AU-038 | B25: Hriday Limaye | C25: 2006-06-21 | D25: Male | E25: 9822514259 | F25: ayaan.sharma38@gmail.com | G25: 217, Aundh Pune | H25: Modern College | I25: 79 | J25: 9960114318 | K25: NEET | L25: 12 | M25: Evening | N25: 2024-01-22 | O25: 2025-01-16 | P25: R-115 | Q25: Offline | R25: Mon-Wed-Fri | S25: Maths | T25: Vikram Joshi | U25: 2024-05-15 | V25: 2024-05-09 | W25: 45733 | X25: 41468 | Y25: 4265 | Z25: 4465 | AA25: Yes | AB25: =RANDBETWEEN(DATE(2025,7,1),DATE(2025,12,31)) -> 45988 | AC25: Partial | AD25: Bank Transfer | AE25: 5 | AF25: 51 | AG25: 58 | AH25: Average | AI25: 65 | AJ25: 56 | AK25: 44 | AM25: 78 | AN25: No | AO25: 1 | AP25: 3 | AQ25: 2024-07-13 | AR25: 2024-07-25 | AS25: No | AT25: Website | AU25: Nidhi Shah | AV25: Active | AX25: =IF(LEFT(A25,2)="AU","Aundh",IF(LEFT(A25,2)="KO","Kondhwa","Sinhgad Road")) -> Aundh
A26: AU-008 | B26: Meera Joshi | C26: 2006-06-23 | D26: Female | E26: 9822355416 | F26: meera.joshi8@gmail.com | G26: 589, Aundh Pune | H26: Vidyanchal School | I26: 88 | J26: 9995712675 | K26: Crash Course | L26: 3 | M26: Afternoon | N26: 2024-03-22 | O26: 2024-06-20 | P26: R-105 | Q26: Online | R26: Tue-Thu-Sat | S26: Physics | T26: Sneha Patil | U26: 2024-03-15 | V26: 2024-03-14 | W26: 40970 | X26: 39997 | Y26: 973 | Z26: 2197 | AA26: No | AB26: =RANDBETWEEN(DATE(2025,7,1),DATE(2025,12,31)) -> 45914 | AC26: Partial | AD26: Bank Transfer | AE26: 6 | AF26: 90 | AG26: 99 | AH26: Average | AI26: 72 | AJ26: 33 | AK26: 25 | AL26: Family function | AM26: 75 | AN26: Yes | AO26: 3 | AP26: 5 | AQ26: 2024-04-08 | AR26: 2024-04-21 | AS26: No | AT26: Referral | AU26: Rahul Mehta | AV26: Active | AX26: =IF(LEFT(A26,2)="AU","Aundh",IF(LEFT(A26,2)="KO","Kondhwa","Sinhgad Road")) -> Aundh
A27: AU-009 | B27: Aryan Apte | C27: 2006-05-21 | D27: Male | E27: 9888752606 | F27: aarav.kumar9@gmail.com | G27: 276, Aundh Pune | H27: City International School | I27: 73 | J27: 9967525295 | K27: Foundation 8-10 | L27: 12 | M27: Afternoon | N27: 2024-03-04 | O27: 2025-02-27 | P27: R-105 | Q27: Online | R27: Mon-Wed-Fri | S27: Chemistry | T27: Vikram Joshi | U27: 2024-03-06 | V27: 2024-03-01 | W27: 21161 | X27: 19825 | Y27: 1336 | Z27: 3988 | AA27: No | AB27: =RANDBETWEEN(DATE(2025,7,1),DATE(2025,12,31)) -> 45987 | AC27: Partial | AD27: UPI | AE27: 8 | AF27: 68 | AG27: 83 | AH27: Good | AI27: 99 | AJ27: 56 | AK27: 41 | AM27: 73 | AN27: No | AO27: 2 | AP27: 5 | AQ27: 2024-04-22 | AR27: 2024-05-21 | AS27: Yes | AT27: Website | AU27: Amit Deshmukh | AV27: Active | AX27: =IF(LEFT(A27,2)="AU","Aundh",IF(LEFT(A27,2)="KO","Kondhwa","Sinhgad Road")) -> Aundh
A28: AU-027 | B28: Siya Desai | C28: 2006-04-22 | D28: Male | E28: 9816439415 | F28: siya.desai27@gmail.com | G28: 969, Aundh Pune | H28: Modern College | I28: 78 | J28: 9925998150 | K28: Crash Course | L28: 6 | M28: Afternoon | N28: 2024-02-02 | O28: 2024-07-31 | P28: R-114 | Q28: Online | R28: Tue-Thu-Sat | S28: Chemistry | T28: Sneha Patil | U28: 2024-03-16 | V28: 2024-03-14 | W28: 45981 | X28: 45836 | Y28: 145 | Z28: 3623 | AA28: Yes | AB28: =RANDBETWEEN(DATE(2025,7,1),DATE(2025,12,31)) -> 45902 | AC28: Partial | AD28: Cash | AE28: 8 | AF28: 74 | AG28: 94 | AH28: Needs Improvement | AI28: 63 | AJ28: 34 | AK28: 25 | AM28: 73 | AN28: No | AO28: 4 | AP28: 5 | AQ28: 2024-05-05 | AR28: 2024-06-04 | AS28: Yes | AT28: Facebook Ad | AU28: Nidhi Shah | AV28: Left | AW28: Switched institute | AX28: =IF(LEFT(A28,2)="AU","Aundh",IF(LEFT(A28,2)="KO","Kondhwa","Sinhgad Road")) -> Aundh
